<?xml version="1.0" ?>
<!-- =================================================================================== -->
<!-- |    This document was autogenerated by xmacro4sdf from model.sdf.xmacro          | -->
<!-- |    EDITING THIS FILE BY HAND IS NOT RECOMMENDED                                 | -->
<!-- =================================================================================== -->
<sdf version="1.7">
	<!--include defination-->
	<!--model-->
	<model canonical_link="gripper_base_link" name="parallel_gripper">
		<pose>0 0 1.0 0 0 0</pose>
		<link name="gripper_base_link">
			<pose relative_to="__model__">0 0 0 0 0 0</pose>
			<inertial>
				<pose>0 0 0.027 0 0 0</pose>
				<mass>0.05</mass>
				<inertia>
					<ixx>1.3816666666666668e-05</ixx>
					<ixy>0</ixy>
					<ixz>0</ixz>
					<iyy>5.635416666666666e-05</iyy>
					<iyz>0</iyz>
					<izz>4.587083333333333e-05</izz>
				</inertia>
			</inertial>
			<collision name="collision">
				<pose>0 0 0 0 0 0</pose>
				<geometry>
					<mesh>
						<uri>model://parallel_gripper/meshes/gripper_base.stl</uri>
					</mesh>
				</geometry>
			</collision>
			<visual name="visual">
				<pose>0 0 0 0 0 0</pose>
				<geometry>
					<mesh>
						<uri>model://parallel_gripper/meshes/gripper_base.stl</uri>
					</mesh>
				</geometry>
				<material>
					<ambient>0.1 0.1 0.1</ambient>
					<diffuse>0.05 0.05 0.05</diffuse>
					<specular>0.6 0.6 0.6</specular>
				</material>
			</visual>
		</link>
		<joint name="left_finger_joint" type="prismatic">
			<pose relative_to="gripper_base_link">-0.043 0 0.0485 0 0 0</pose>
			<parent>gripper_base_link</parent>
			<child>left_finger_link</child>
			<axis>
				<limit>
					<lower>0</lower>
					<upper>0.25</upper>
				</limit>
				<xyz>1 0 0</xyz>
			</axis>
		</joint>
		<link name="left_finger_link">
			<pose relative_to="left_finger_joint">0 0 0 0 0 0</pose>
			<inertial>
				<pose>0 0 0.020 0 0 0</pose>
				<mass>0.01</mass>
				<inertia>
					<ixx>2.781666666666667e-06</ixx>
					<ixy>0</ixy>
					<ixz>0</ixz>
					<iyy>2.948333333333333e-06</iyy>
					<iyz>0</iyz>
					<izz>1.0483333333333334e-06</izz>
				</inertia>
			</inertial>
			<collision name="collision">
				<pose>0 0 0 0 0 0</pose>
				<geometry>
					<mesh>
						<uri>model://parallel_gripper/meshes/finger.stl</uri>
					</mesh>
				</geometry>
			</collision>
			<visual name="visual">
				<pose>0 0 0 0 0 0</pose>
				<geometry>
					<mesh>
						<uri>model://parallel_gripper/meshes/finger.stl</uri>
					</mesh>
				</geometry>
				<material>
					<ambient>0.1 0.1 0.1</ambient>
					<diffuse>0.05 0.05 0.05</diffuse>
					<specular>0.6 0.6 0.6</specular>
				</material>
			</visual>
		</link>
		<joint name="right_finger_joint" type="prismatic">
			<pose relative_to="gripper_base_link">0.043 0 0.0485 0 0 3.14159</pose>
			<parent>gripper_base_link</parent>
			<child>right_finger_link</child>
			<axis>
				<limit>
					<lower>0</lower>
					<upper>0.25</upper>
				</limit>
				<xyz>1 0 0</xyz>
			</axis>
		</joint>
		<link name="right_finger_link">
			<pose relative_to="right_finger_joint">0 0 0 0 0 0</pose>
			<inertial>
				<pose>0 0 0.020 0 0 0</pose>
				<mass>0.01</mass>
				<inertia>
					<ixx>2.781666666666667e-06</ixx>
					<ixy>0</ixy>
					<ixz>0</ixz>
					<iyy>2.948333333333333e-06</iyy>
					<iyz>0</iyz>
					<izz>1.0483333333333334e-06</izz>
				</inertia>
			</inertial>
			<collision name="collision">
				<pose>0 0 0 0 0 0</pose>
				<geometry>
					<mesh>
						<uri>model://parallel_gripper/meshes/finger.stl</uri>
					</mesh>
				</geometry>
			</collision>
			<visual name="visual">
				<pose>0 0 0 0 0 0</pose>
				<geometry>
					<mesh>
						<uri>model://parallel_gripper/meshes/finger.stl</uri>
					</mesh>
				</geometry>
				<material>
					<ambient>0.1 0.1 0.1</ambient>
					<diffuse>0.05 0.05 0.05</diffuse>
					<specular>0.6 0.6 0.6</specular>
				</material>
			</visual>
		</link>
		<joint name="world_parallel_gripper_joint" type="fixed">
			<parent>world</parent>
			<child>gripper_base_link</child>
		</joint>
		<!--plugins for parallel_gripper-->
		<plugin filename="ignition-gazebo-joint-position-controller-system" name="ignition::gazebo::systems::JointPositionController">
			<joint_name>left_finger_joint</joint_name>
			<p_gain>100</p_gain>
			<i_gain>2</i_gain>
			<d_gain>5</d_gain>
			<i_max>100.0</i_max>
			<i_min>-100.0</i_min>
		</plugin>
		<plugin filename="ignition-gazebo-joint-position-controller-system" name="ignition::gazebo::systems::JointPositionController">
			<joint_name>right_finger_joint</joint_name>
			<p_gain>100</p_gain>
			<i_gain>2</i_gain>
			<d_gain>5</d_gain>
			<i_max>100.0</i_max>
			<i_min>-100.0</i_min>
		</plugin>
	</model>
</sdf>

